Workbook
Name GroupList: Lists!$A$2:$A$15
Name SG_1: Lists!$B$2:$B$9
Name SG_2: Lists!$C$2:$C$5
Name SG_3: Lists!$D$2:$D$5
Name SG_4: Lists!$E$2:$E$6
Name SG_5: Lists!$F$2:$F$5
Name SG_6: Lists!$G$2:$G$6
Name SG_7: Lists!$H$2:$H$4
Name SG_8: Lists!$I$2:$I$5
Name SG_9: Lists!$J$2:$J$3
Name SG_10: Lists!$K$2:$K$15
Name SG_11: Lists!$L$2:$L$2
Name SG_12: Lists!$M$2:$M$4
Name SG_13: Lists!$N$2:$N$17
Name SG_14: Lists!$O$2:$O$2

Sheet READ ME
A1: Silver Muller Seals - Master Data Upload Template
A3: What this file is for
A4: Enter your items on the 'Other Item Master' sheet (non-FG items) or the 'FG Item Master' sheet (finished goods). Enter suppliers on the 'Supplier Master' sheet. Link suppliers to items on the 'Supplier-Item Map' sheet.
A5: Each row is one item, one supplier, or one supplier-item link. Start at row 2; row 1 holds the column names.
A7: Colour key
A8: Red column heading with * = MANDATORY (must be filled).
A9: Blue column heading = optional (can be left blank; the default in the guide is used).
A11: How to fill it
A12: 1. Read the matching 'Field Guide' sheet: it lists every column, whether it is mandatory and what values are accepted.
A13: 2. Columns with a dropdown: click the cell and choose from the list. Selecting a cell also shows the accepted values.
A14: 3. Do not rename, delete, or reorder the column headings.
A15: 4. Do not put formulas in the sheet; type the values.
... A23: Dropdown values come from the system's current lists. If a group, HSN code or category you need is missing, tell us before filling the file.

Sheet Other Item Master
A1: Group * | B1: Sub-Group * | C1: Sub-SubGroup * | D1: ITEM Code * | E1: Old Code | F1: Item Description * | G1: ID (in mm) | H1: OD (in mm) | I1: Height (in mm) | J1: Thickness (in mm) | K1: Color | L1: Mtrl (Material) | M1: Style | N1: Drawing No. | O1: Drawing Image (file name) | P1: Image (file name) | Q1: Safety Lead Time (days) | R1: Procurement Lead Time (days) | S1: Purchase UOM | T1: Consumed UOM | U1: Opening Balance | V1: Gross Wt (in gram) | W1: Net Wt (in gram) | X1: Class | Y1: Rej % Tolerance | Z1: Procurement Type | AA1: Process Type | AB1: HSN / SAC Code * | AC1: Min Stock Lvl | AD1: Max Stock Lvl | AE1: Reorder Stock Lvl | AF1: MRP | AG1: Rate

Sheet Other Item Field Guide
A1: Other Item Master - field guide
A3: # | B3: Column name | C3: Mandatory? | D3: Type | E3: Accepted values / format | F3: Max length | G3: Default if blank | H3: Example | I3: Saved to system field?
A4: 1 | B4: Group | C4: Yes | D4: Dropdown | E4: Pick from the dropdown: one of the 13 non-FG groups. The group must already exist in Item Groups. | F4: - | G4: - | H4: Raw Material | I4: group_name
A5: 2 | B5: Sub-Group | C5: Yes | D5: Dropdown | E5: Pick from the dropdown. The list depends on the Group chosen in the same row. | F5: 255 | G5: - | H5: Primary Raw Material | I5: subgroup
A6: 3 | B6: Sub-SubGroup | C6: Yes | D6: Dropdown | E6: Pick from the dropdown: a subgroup of the same Group (usually the same as Sub-Group). | F6: 255 | G6: - | H6: Primary Raw Material | I6: sub_subgroup
A7: 4 | B7: ITEM Code | C7: Yes | D7: Text | E7: Text. Must be unique across the whole item list. | F7: 255 | G7: - | H7: RM01-0001 | I7: sms_new_part_no
A8: 5 | B8: Old Code | C8: No | D8: Text | E8: Text. Customer's or previous part number. | F8: 255 | G8: blank | H8: OLD-1001 | I8: old_code
A9: 6 | B9: Item Description | C9: Yes | D9: Text | E9: Text. Must be unique: two items cannot have the same description. | F9: - | G9: - | H9: NBR Compound Sheet 2 mm | I9: description_size
A10: 7 | B10: ID (in mm) | C10: No | D10: Text | E10: Number, in mm. | F10: 255 | G10: blank | H10: 25 | I10: inner_diameter
A11: 8 | B11: OD (in mm) | C11: No | D11: Text | E11: Number, in mm. | F11: 255 | G11: blank | H11: 40 | I11: outer_diameter
A12: 9 | B12: Height (in mm) | C12: No | D12: Text | E12: Number, in mm. | F12: 255 | G12: blank | H12: 7 | I12: width
A13: 10 | B13: Thickness (in mm) | C13: No | D13: Text | E13: Number, in mm. | F13: 255 | G13: blank | H13: 2 | I13: thickness
A14: 11 | B14: Color | C14: No | D14: Text | E14: Text. | F14: 255 | G14: blank | H14: Black | I14: color
A15: 12 | B15: Mtrl (Material) | C15: No | D15: Text | E15: Text. Material grade, for example NBR, FKM, EN8. | F15: 255 | G15: blank | H15: NBR | I15: material
A16: 13 | B16: Style | C16: No | D16: Dropdown | E16: Pick from the dropdown. | F16: - | G16: blank | H16: 1. Rubber | I16: style
A17: 14 | B17: Drawing No. | C17: No | D17: Text | E17: Text. | F17: 255 | G17: blank | H17: DWG-1001 | I17: drawing_no
A18: 15 | B18: Drawing Image (file name) | C18: No | D18: Image file name | E18: File name of a JPG, JPEG, PNG or WEBP image, including the extension. Send the image files together with this workbook, named exactly as written here. | F18: 255 | G18: blank | H18: RM01-0001-drawing.png | I18: drawing_image
A19: 16 | B19: Image (file name) | C19: No | D19: Image file name | E19: File name of a JPG, JPEG, PNG or WEBP image, including the extension. Send the image files together with this workbook, named exactly as written here. | F19: 255 | G19: blank | H19: RM01-0001.jpg | I19: image
A20: 17 | B20: Safety Lead Time (days) | C20: No | D20: Number | E20: Number of days, 0 or more. | F20: 0 to 1e+08 | G20: 0 | H20: 3 | I20: safety_lead_time
A21: 18 | B21: Procurement Lead Time (days) | C21: No | D21: Number | E21: Number of days, 0 or more. | F21: 0 to 1e+08 | G21: 0 | H21: 15 | I21: procurement_lead_time
A22: 19 | B22: Purchase UOM | C22: No | D22: Dropdown | E22: Pick from the dropdown. | F22: 100 | G22: PCS | H22: KG | I22: purchased_uom
A23: 20 | B23: Consumed UOM | C23: No | D23: Dropdown | E23: Pick from the dropdown. | F23: 100 | G23: same as Purchase UOM | H23: KG | I23: consumption_uom
A24: 21 | B24: Opening Balance | C24: No | D24: Number | E24: Number, 0 or more, up to 3 decimals. | F24: 0 to 1e+12 | G24: blank | H24: 100 | I24: opening_balance
A25: 22 | B25: Gross Wt (in gram) | C25: No | D25: Number | E25: Number, grams, 0 or more. | F25: 0 to 1e+12 | G25: blank | H25: 18.5 | I25: gross_wt
A26: 23 | B26: Net Wt (in gram) | C26: No | D26: Number | E26: Number, grams, 0 or more. | F26: 0 to 1e+12 | G26: blank | H26: 16.2 | I26: net_wt
A27: 24 | B27: Class | C27: No | D27: Dropdown | E27: Pick from the dropdown: High, Medium or Low. | F27: - | G27: blank | H27: High | I27: item_class
A28: 25 | B28: Rej % Tolerance | C28: No | D28: Number | E28: Number from 0 to 100 (percent). | F28: 0 to 100 | G28: blank | H28: 2 | I28: rej_tolerance
A29: 26 | B29: Procurement Type | C29: No | D29: Dropdown | E29: Pick from the dropdown. | F29: - | G29: blank | H29: IN HOUSE | I29: procurement_type
A30: 27 | B30: Process Type | C30: No | D30: Dropdown | E30: Pick the process code from the dropdown (PR-1 ... PR-16). | F30: - | G30: blank | H30: PR-1 | I30: process_type
A31: 28 | B31: HSN / SAC Code | C31: Yes for new items | D31: Dropdown | E31: Pick from the dropdown. Required when adding a new item. | F31: 50 | G31: blank | H31: 40021990 | I31: hsn_code
... A36: 33 | B36: Rate | C36: No | D36: Number | E36: Number, 0 or more, 2 decimals. INR. | F36: 0 to 1e+13 | G36: 0.00 | H36: 45.50 | I36: price

Sheet FG Item Master
A1: Group (Product) * | B1: Sub-Group (Segment) * | C1: Sub-SubGroup (Region) * | D1: ITEM Code * | E1: Old Code | F1: Item Description * | G1: ID (in mm) | H1: OD (in mm) | I1: Height (in mm) | J1: Thickness (in mm) | K1: Color | L1: Mtrl (Material) | M1: Style | N1: Drawing No. | O1: Drawing Image (file name) | P1: Image (file name) | Q1: Safety Lead Time (days) | R1: Procurement Lead Time (days) | S1: Purchase UOM | T1: Consumed UOM | U1: Opening Balance | V1: Gross Wt (in gram) | W1: Net Wt (in gram) | X1: Class | Y1: Rej % Tolerance | Z1: Procurement Type | AA1: Process Type | AB1: Min Stock Lvl | AC1: Max Stock Lvl | AD1: Reorder Stock Lvl | AE1: HSN / SAC Code * | AF1: MRP | AG1: Rate | AH1: Category | AI1: Domestic / Exports | AJ1: Application | AK1: REF. NO. | AL1: OEM Reference | AM1: CORTECO NO | AN1: CROSS Reference | AO1: Remark (Main FG Code) | AP1: Fitting Position | AQ1: Swirl Type | AR1: File Name (CAD / Drawing) | AS1: FG Outsource | AT1: SFG Outsource | AU1: Outsource Combo FG & SFG

Sheet FG Item Field Guide
A1: FG Item Master - field guide
A3: # | B3: Column name | C3: Mandatory? | D3: Type | E3: Accepted values / format | F3: Max length | G3: Default if blank | H3: Example | I3: Saved to system field?
A4: 1 | B4: Group (Product) | C4: Yes | D4: Dropdown | E4: Pick from the dropdown (OIL SEAL, VALVE STEAM SEAL, O-RING, ...). | F4: - | G4: - | H4: OIL SEAL | I4: subgroup
A5: 2 | B5: Sub-Group (Segment) | C5: Yes | D5: Dropdown | E5: Pick from the dropdown: vehicle or application segment. | F5: - | G5: - | H5: Trucks / HCV | I5: segment
A6: 3 | B6: Sub-SubGroup (Region) | C6: Yes | D6: Dropdown | E6: Pick from the dropdown: market or design origin. | F6: - | G6: - | H6: EUROPEAN | I6: region
A7: 4 | B7: ITEM Code | C7: Yes | D7: Text | E7: Text. Must be unique across the whole item list. | F7: 255 | G7: - | H7: FG-987-00001 | I7: sms_new_part_no
A8: 5 | B8: Old Code | C8: No | D8: Text | E8: Text. | F8: 255 | G8: blank | H8: 12015 | I8: old_code
A9: 6 | B9: Item Description | C9: Yes | D9: Text | E9: Text. Must be unique: two items cannot have the same description. | F9: - | G9: - | H9: OIL SEAL 35*50*8 NBR | I9: description_size
A10: 7 | B10: ID (in mm) | C10: No | D10: Number | E10: Number, in mm. | F10: 0 to 1e+12 | G10: blank | H10: 35 | I10: inner_diameter
A11: 8 | B11: OD (in mm) | C11: No | D11: Number | E11: Number, in mm. | F11: 0 to 1e+12 | G11: blank | H11: 50 | I11: outer_diameter
A12: 9 | B12: Height (in mm) | C12: No | D12: Number | E12: Number, in mm. | F12: 0 to 1e+12 | G12: blank | H12: 8 | I12: width
A13: 10 | B13: Thickness (in mm) | C13: No | D13: Number | E13: Number, in mm. | F13: 0 to 1e+12 | G13: blank | H13: 2 | I13: thickness
A14: 11 | B14: Color | C14: No | D14: Text | E14: Text. | F14: 255 | G14: blank | H14: Black | I14: color
A15: 12 | B15: Mtrl (Material) | C15: No | D15: Text | E15: Text. Material grade, for example NBR, FKM. | F15: 255 | G15: blank | H15: NBR | I15: material
A16: 13 | B16: Style | C16: No | D16: Dropdown | E16: Pick from the dropdown: Rubber, Metal or Other. | F16: - | G16: blank | H16: Rubber | I16: style
A17: 14 | B17: Drawing No. | C17: No | D17: Text | E17: Text. | F17: 255 | G17: blank | H17: DWG-001 | I17: drawing_no
A18: 15 | B18: Drawing Image (file name) | C18: No | D18: Image file name | E18: File name of a JPG, JPEG, PNG or WEBP image, including the extension. Send the image files together with this workbook, named exactly as written here. | F18: 255 | G18: blank | H18: FG-987-00001-drawing.png | I18: drawing_image
A19: 16 | B19: Image (file name) | C19: No | D19: Image file name | E19: File name of a JPG, JPEG, PNG or WEBP image, including the extension. Send the image files together with this workbook, named exactly as written here. | F19: 255 | G19: blank | H19: FG-987-00001.jpg | I19: image
A20: 17 | B20: Safety Lead Time (days) | C20: No | D20: Number | E20: Number of days, 0 or more. | F20: 0 to 1e+08 | G20: 0 | H20: 3 | I20: safety_lead_time
A21: 18 | B21: Procurement Lead Time (days) | C21: No | D21: Number | E21: Number of days, 0 or more. | F21: 0 to 1e+08 | G21: 0 | H21: 15 | I21: procurement_lead_time
A22: 19 | B22: Purchase UOM | C22: No | D22: Dropdown | E22: Pick from the dropdown. | F22: 100 | G22: PCS | H22: PCS | I22: purchased_uom
A23: 20 | B23: Consumed UOM | C23: No | D23: Dropdown | E23: Pick from the dropdown. | F23: 100 | G23: same as Purchase UOM | H23: PCS | I23: consumption_uom
A24: 21 | B24: Opening Balance | C24: No | D24: Number | E24: Number, 0 or more, up to 3 decimals. | F24: 0 to 1e+12 | G24: blank | H24: 100 | I24: opening_balance
A25: 22 | B25: Gross Wt (in gram) | C25: No | D25: Number | E25: Number, grams, 0 or more. | F25: 0 to 1e+12 | G25: blank | H25: 18.5 | I25: gross_wt
A26: 23 | B26: Net Wt (in gram) | C26: No | D26: Number | E26: Number, grams, 0 or more. | F26: 0 to 1e+12 | G26: blank | H26: 16.2 | I26: net_wt
A27: 24 | B27: Class | C27: No | D27: Dropdown | E27: Pick from the dropdown: High, Medium or Low. | F27: - | G27: blank | H27: High | I27: item_class
A28: 25 | B28: Rej % Tolerance | C28: No | D28: Number | E28: Number from 0 to 100 (percent). | F28: 0 to 100 | G28: blank | H28: 2 | I28: rej_tolerance
A29: 26 | B29: Procurement Type | C29: No | D29: Dropdown | E29: Pick from the dropdown. | F29: - | G29: blank | H29: IN HOUSE | I29: procurement_type
A30: 27 | B30: Process Type | C30: No | D30: Dropdown | E30: Pick the process code from the dropdown (PR-1 ... PR-16). | F30: - | G30: blank | H30: PR-1 | I30: process_type
A31: 28 | B31: Min Stock Lvl | C31: No | D31: Number | E31: Number, 0 or more. Cannot be above Max Stock Lvl. | F31: 0 to 1e+12 | G31: blank | H31: 50 | I31: min_stock_lvl
... A36: 33 | B36: Rate | C36: No | D36: Number | E36: Number, 0 or more, 2 decimals. INR. | F36: 0 to 1e+13 | G36: 0.00 | H36: 45.50 | I36: price
A37: 34 | B37: Category | C37: No | D37: Text | E37: Text, for example Oil Seal, O-Ring, Gasket. | F37: 255 | G37: FG | H37: Oil Seal | I37: category
A38: 35 | B38: Domestic / Exports | C38: No | D38: Dropdown | E38: Pick from the dropdown: Domestic, Export or Both. | F38: - | G38: blank | H38: Domestic | I38: domestic_exports
A39: 36 | B39: Application | C39: No | D39: Text | E39: Text, for example Engine Crankshaft, Wheel Hub. | F39: 255 | G39: blank | H39: Wheel Hub | I39: application
A40: 37 | B40: REF. NO. | C40: No | D40: Text | E40: Text. | F40: 255 | G40: blank | H40: REF-778 | I40: ref_no
A41: 38 | B41: OEM Reference | C41: No | D41: Text | E41: Text. | F41: 255 | G41: blank | H41: Bosch 1234 | I41: oem
A42: 39 | B42: CORTECO NO | C42: No | D42: Text | E42: Text. | F42: 255 | G42: blank | H42: 19033588 | I42: corteco_no
A43: 40 | B43: CROSS Reference | C43: No | D43: Text | E43: Text. | F43: 255 | G43: blank | H43: XR-9 | I43: cross_reference
A44: 41 | B44: Remark (Main FG Code) | C44: No | D44: Text | E44: Text. The main FG code this item belongs to. | F44: 255 | G44: blank | H44: FG-0456 | I44: main_fg_code
A45: 42 | B45: Fitting Position | C45: No | D45: Text | E45: Text. | F45: 255 | G45: blank | H45: Front | I45: fitting_position
...

Sheet Supplier Master
A1: Supplier Name * | B1: Supplier Code | C1: Supplier Type | D1: GSTIN | E1: PAN | F1: Udyam No | G1: MSME Category | H1: GST Registration Type | I1: TDS Section | J1: Contact Person | K1: Email | L1: Phone | M1: Payment Terms | N1: Currency | O1: Status | P1: Address | Q1: City | R1: State | S1: State Code | T1: Pincode | U1: Company ID

Sheet Supplier Field Guide
A1: Supplier Master - field guide
A3: # | B3: Column name | C3: Mandatory? | D3: Type | E3: Accepted values / format | F3: Max length | G3: Default if blank | H3: Example | I3: Saved to system field?
A4: 1 | B4: Supplier Name | C4: Yes | D4: Text | E4: Text. The legal name of the supplier. | F4: 255 | G4: - | H4: ABC Rubber Industries Pvt Ltd | I4: supplier_name
A5: 2 | B5: Supplier Code | C5: No | D5: Text | E5: Text. Must be unique. Leave blank and the system creates one (SUP-001, SUP-002, ...). Needed if the supplier has items in the Supplier-Item Map. | F5: 50 | G5: auto-generated | H5: SUP-0001 | I5: supplier_code
A6: 3 | B6: Supplier Type | C6: No | D6: Dropdown | E6: Pick from the dropdown. | F6: 50 | G6: MATERIAL | H6: MATERIAL | I6: supplier_type
A7: 4 | B7: GSTIN | C7: No | D7: Text (fixed length) | E7: Exactly 15 characters, for example 27AABCU9603R1ZX. First 2 digits = state code; characters 3-12 = PAN. | F7: 15 characters | G7: blank | H7: 27AABCU9603R1ZX | I7: gstin
A8: 5 | B8: PAN | C8: No | D8: Text (fixed length) | E8: Exactly 10 characters, format AAAAA9999A. Filled automatically from GSTIN if left blank. | F8: 10 characters | G8: from GSTIN | H8: AABCU9603R | I8: pan
A9: 6 | B9: Udyam No | C9: No | D9: Text | E9: Text. Udyam registration number if the supplier is MSME. | F9: 50 | G9: blank | H9: UDYAM-MH-00-0000000 | I9: udyam_no
A10: 7 | B10: MSME Category | C10: No | D10: Dropdown | E10: Pick from the dropdown. | F10: 50 | G10: NOT_MSME | H10: NOT_MSME | I10: msme_category
A11: 8 | B11: GST Registration Type | C11: No | D11: Dropdown | E11: Pick from the dropdown. | F11: 50 | G11: REGISTERED | H11: REGISTERED | I11: gst_registration_type
A12: 9 | B12: TDS Section | C12: No | D12: Text | E12: Text, for example TDS-194C. | F12: 50 | G12: TDS-194C | H12: TDS-194C | I12: tds_section_id
A13: 10 | B13: Contact Person | C13: No | D13: Text | E13: Text. | F13: 255 | G13: blank | H13: Ramesh Patil | I13: contact_person
A14: 11 | B14: Email | C14: No | D14: Text | E14: Text, with @ and a domain, for example name@company.com. | F14: 255 | G14: blank | H14: sales@example.com | I14: email
A15: 12 | B15: Phone | C15: No | D15: Text | E15: Text or digits. Mobile or landline with STD code. | F15: 50 | G15: blank | H15: 9876543210 | I15: phone
A16: 13 | B16: Payment Terms | C16: No | D16: Dropdown | E16: Pick from the dropdown. PT-15 = 15 Days, PT-30 = 30 Days, PT-45 = 45 Days, PT-60 = 60 Days, IMMEDIATE = Advance / Immediate. | F16: 50 | G16: PT-30 | H16: PT-30 | I16: payment_terms_id
A17: 14 | B17: Currency | C17: No | D17: Text | E17: Currency code, for example INR. | F17: 10 | G17: INR | H17: INR | I17: currency
A18: 15 | B18: Status | C18: No | D18: Dropdown | E18: Pick from the dropdown. | F18: 30 | G18: ACTIVE | H18: ACTIVE | I18: status
A19: 16 | B19: Address | C19: No | D19: Text | E19: Text. Full address. | F19: - | G19: blank | H19: Plot 12, MIDC Industrial Area | I19: address
A20: 17 | B20: City | C20: No | D20: Text | E20: Text. | F20: 100 | G20: blank | H20: Pune | I20: city
A21: 18 | B21: State | C21: No | D21: Text | E21: Text, the state name. | F21: 100 | G21: blank | H21: Maharashtra | I21: state
A22: 19 | B22: State Code | C22: No | D22: Text | E22: 2-digit GST state code, for example 27. Filled from GSTIN if left blank. | F22: 10 | G22: from GSTIN | H22: 27 | I22: state_code
A23: 20 | B23: Pincode | C23: No | D23: Text | E23: 6 digits. | F23: 20 | G23: blank | H23: 411019 | I23: pincode
A24: 21 | B24: Company ID | C24: No | D24: Text | E24: Text. | F24: 50 | G24: COMP-001 | H24: COMP-001 | I24: company_id
A27: Supplier-Item Map sheet (supplier to item association)
A28: # | B28: Column name | C28: Mandatory? | D28: Type | E28: Accepted values / format | F28: Max length | G28: Default if blank | H28: Example | I28: Saved to system field?
A29: 1 | B29: Supplier Code | C29: Yes | D29: Dropdown | E29: Pick a Supplier Code that exists on the Supplier Master sheet. A supplier with no code cannot be mapped: fill its Supplier Code. | F29: 50 | G29: - | H29: SUP-0001 | I29: supplier_master.supplier_code
A30: 2 | B30: Item Code (SMS Part No.) | C30: Yes | D30: Dropdown | E30: Pick an Item Code that exists on the Other Item Master or FG Item Master sheet. Add one row for each item the supplier is associated with: a supplier can have any number of items. | F30: 255 | G30: - | H30: RM-00001 | I30: supplier_item.item_id (via item code)

Sheet Supplier-Item Map
A1: Supplier Code * | B1: Item Code (SMS Part No.) *

Sheet Lists
A1: Group | B1: Subgroups of FG | C1: Subgroups of Assets | D1: Subgroups of Bought-Out Parts | E1: Subgroups of Consumables | F1: Subgroups of IT & Communication | G1: Subgroups of Maintenance, Repair & Operations | H1: Subgroups of Office & Administration | I1: Subgroups of Packing Materials | J1: Subgroups of Production | K1: Subgroups of Raw Material | L1: Subgroups of Safety & PPE | M1: Subgroups of Services | N1: Subgroups of SFG | O1: Subgroups of Uniforms & Linen | P1: Category | Q1: UOM | R1: HSN / SAC code | S1: FG product group | T1: FG sub-group (segment) | U1: FG sub-subgroup (region) | V1: FG style | W1: FG class | X1: FG procurement type | Y1: FG process type | Z1: FG domestic / exports | AA1: FG swirl type | AB1: FG UOM | AC1: FG outsource | AD1: SFG outsource | AE1: Outsource combo FG & SFG | AF1: Other item style | AG1: Other item group | AH1: Supplier type | AI1: MSME category | AJ1: GST registration type | AK1: Payment terms | AL1: Supplier status | AM1: All item codes
A2: FG | B2: Trucks / HCV | C2: Die | D2: Electrical Components | E2: Maintenance Consumables | F2: Fresh IT Gadgets | G2: Electrical Maintenance Items | H2: Housekeeping Supplies | I2: Packaging Raw Materials | J2: Die Domestic | K2: Customer Supplied Materials | L2: Personal Protective Equipment | M2: Contractual/Facility Services | N2: Big Washer | O2: Uniforms & Textiles | P2: Big Washer | Q2: PCS | R2: 27101980 | S2: OIL SEAL | T2: Trucks / HCV | U2: EUROPEAN | V2: Rubber | W2: High | X2: IN HOUSE | Y2: PR-1 | Z2: Domestic | AA2: None | AB2: PCS | AC2: IH | AD2: IH | AE2: IH | AF2: 1. Rubber | AG2: Assets | AH2: MATERIAL | AI2: NOT_MSME | AJ2: REGISTERED | AK2: PT-15 | AL2: ACTIVE | AM2: =IF('Other Item Master'!D2="","",'Other Item Master'!D2)
A3: Assets | B3: LCV/SCV | C3: High Valued Assets | D3: Electronic Modules | E3: Office Consumables / Furniture & Fixture | F3: Networking Devices | G3: General Maintenance Item/Assets | H3: Office Stationery | I3: Primary Packaging | J3: Die Export | K3: Hazardous Raw Materials | M3: Professional Services | N3: Brass Washer | P3: Brass Washer | Q3: NOS | R3: 27101990 | S3: VALVE STEAM SEAL | T3: LCV/SCV | U3: AMERICAN | V3: Metal | W3: Medium | X3: OUTSOURCE | Y3: PR-2 | Z3: Export | AA3: Right Hand (RH) | AB3: NOS | AC3: RING OS | AD3: RING OS | AE3: RING OS | AF3: 2. Metal | AG3: Bought-Out Parts | AH3: SERVICES | AI3: MICRO | AJ3: UNREGISTERED | AK3: PT-30 | AL3: INACTIVE | AM3: =IF('Other Item Master'!D3="","",'Other Item Master'!D3)
A4: Bought-Out Parts | B4: Automotive/Passenger/4W | C4: Low Valued Assets - Equipment | D4: Mechanical Assemblies | E4: Production Consumables | F4: Repaired Items | G4: HVAC & Air Handling Components / Air Conditioning Components | H4: Pantry & Refreshment Items | I4: Secondary Packaging | K4: Imported Raw Materials | M4: Technical Services | N4: FELT | P4: Consumables | Q4: SET | R4: 28020010 | S4: O-RING | T4: Automotive/Passenger/4W | U4: JAPANESE | V4: Other | W4: Low | X4: BUY/INHOUSE | Y4: PR-3 | Z4: Both | AA4: Left Hand (LH) | AB4: SET | AC4: MOULDED OS | AD4: MOULDED OS | AE4: MOULDED OS | AF4: 3. Other | AG4: Consumables | AH4: LOGISTICS | AI4: SMALL | AJ4: COMPOSITION | AK4: PT-45 | AL4: BLOCKED | AM4: =IF('Other Item Master'!D4="","",'Other Item Master'!D4)
A5: Consumables | B5: AGRICULTURAL/Tractor | C5: Low Valued Assets - Material Handling Objects | D5: Supporting/Accessory for FG/SFG | E5: Quality & Lab Consumables | F5: Used IT Gadgets | G5: Mechanical Items | I5: Used Packaging | K5: Primary Raw Material | N5: Gasket | P5: FELT | Q5: MTR | R5: 28030010 | S5: O-RING KIT | T5: AGRICULTURAL/Tractor | U5: CHINESE | X5: IMPORTED | Y5: PR-4 | AA5: Bi-Directional | AB5: MTR | AC5: FULL OS | AD5: JOBWORK | AE5: COMBO OS | AG5: IT & Communication | AH5: CONTRACTOR | AI5: MEDIUM | AJ5: SEZ | AK5: PT-60 | AM5: =IF('Other Item Master'!D5="","",'Other Item Master'!D5)
A6: IT & Communication | B6: Construction | E6: Tool Room Consumables | G6: Utilities Spares | K6: Primary Raw Material - Sand | N6: INNER METAL SHELL | P6: FG | Q6: KGS | R6: 28170010 | S6: METAL PARTS | T6: Construction | U6: IND | Y6: PR-5 | AB6: KGS | AG6: Maintenance, Repair & Operations | AK6: IMMEDIATE | AM6: =IF('Other Item Master'!D6="","",'Other Item Master'!D6)
A7: Maintenance, Repair & Operations | B7: INDUS. | K7: Primary Raw Material Compound Chemical | N7: INNER MOULDED | P7: Gasket | Q7: KG | R7: 34039900 | S7: ABS RING | T7: INDUS. | U7: CIS | Y7: PR-7 | AG7: Office & Administration | AM7: =IF('Other Item Master'!D7="","",'Other Item Master'!D7)
A8: Office & Administration | B8: 3 W | K8: Primary Raw Material Compound Rubber | N8: MIDDLE METAL SHELL | P8: INNER METAL SHELL | Q8: LTR | R8: 35069190 | S8: PU | T8: 3 W | Y8: PR-8 | AG8: Packing Materials | AM8: =IF('Other Item Master'!D8="","",'Other Item Master'!D8)
A9: Packing Materials | B9: 2 W | K9: Primary Raw Material Final Part Paint | N9: O-Ring | P9: INNER MOULDED | Q9: BOX | R9: 38249990 | S9: REPAIR KIT | T9: 2 W | Y9: PR-9 | AG9: Production | AM9: =IF('Other Item Master'!D9="","",'Other Item Master'!D9)
A10: Production | K10: Primary Raw Material Finishing Spring | N10: OTHER | P10: MIDDLE METAL SHELL | Q10: ROLL | R10: 39046100 | S10: GASKET/WHEEL HUB | Y10: PR-10 | AG10: Raw Material | AM10: =IF('Other Item Master'!D10="","",'Other Item Master'!D10)
A11: Raw Material | K11: Primary Raw Materials - Tool Room | N11: OUTER METAL SHELL | P11: MIDDLE MOULDED | Q11: DRUM | R11: 39232990 | Y11: PR-11 | AG11: Safety & PPE | AM11: =IF('Other Item Master'!D11="","",'Other Item Master'!D11)
A12: Safety & PPE | K12: Processed Raw Materials | N12: OUTER MOULDED | P12: O-Ring | R12: 39269099 | Y12: PR-12 | AG12: Services | AM12: =IF('Other Item Master'!D12="","",'Other Item Master'!D12)
A13: Services | K13: Recycled Raw Materials | N13: PTFE | P13: O-RING-A | R13: 40021990 | Y13: PR-13 | AG13: SFG | AM13: =IF('Other Item Master'!D13="","",'Other Item Master'!D13)
A14: SFG | K14: Seasonal / Project-Specific Raw Materials | N14: SFG-TOOL ROOM | P14: O-RING-B | R14: 40027000 | Y14: PR-14 | AG14: Uniforms & Linen | AM14: =IF('Other Item Master'!D14="","",'Other Item Master'!D14)
A15: Uniforms & Linen | K15: Secondary Raw Materials | N15: Silver Washer | P15: O-RING-C | R15: 40029990 | Y15: PR-15 | AM15: =IF('Other Item Master'!D15="","",'Other Item Master'!D15)
N16: SPRING | P16: O-RING-D | R16: 40051000 | Y16: PR-51 | AM16: =IF('Other Item Master'!D16="","",'Other Item Master'!D16)
N17: TPU/PU | P17: OUTER METAL SHELL | R17: 40082110 | Y17: PR-16 | AM17: =IF('Other Item Master'!D17="","",'Other Item Master'!D17)
P18: OUTER MOULDED | R18: 40169320 | AM18: =IF('Other Item Master'!D18="","",'Other Item Master'!D18)
P19: PTFE | R19: 40169330 | AM19: =IF('Other Item Master'!D19="","",'Other Item Master'!D19)
P20: Raw Material | R20: 40169340 | AM20: =IF('Other Item Master'!D20="","",'Other Item Master'!D20)
P21: Silver Washer | R21: 40169990 | AM21: =IF('Other Item Master'!D21="","",'Other Item Master'!D21)
P22: Spare Parts | R22: 6310 | AM22: =IF('Other Item Master'!D22="","",'Other Item Master'!D22)
P23: SPRING | R23: 72091600 | AM23: =IF('Other Item Master'!D23="","",'Other Item Master'!D23)
P24: TPU/PU | R24: 72104900 | AM24: =IF('Other Item Master'!D24="","",'Other Item Master'!D24)
R25: 72283000 | AM25: =IF('Other Item Master'!D25="","",'Other Item Master'!D25)
R26: 73181500 | AM26: =IF('Other Item Master'!D26="","",'Other Item Master'!D26)
R27: 73182100 | AM27: =IF('Other Item Master'!D27="","",'Other Item Master'!D27)
R28: 73182910 | AM28: =IF('Other Item Master'!D28="","",'Other Item Master'!D28)
R29: 73202000 | AM29: =IF('Other Item Master'!D29="","",'Other Item Master'!D29)
R30: 73209090 | AM30: =IF('Other Item Master'!D30="","",'Other Item Master'!D30)
R31: 73269099 | AM31: =IF('Other Item Master'!D31="","",'Other Item Master'!D31)
R32: 82073000 | AM32: =IF('Other Item Master'!D32="","",'Other Item Master'!D32)
R33: 84669390 | AM33: =IF('Other Item Master'!D33="","",'Other Item Master'!D33)
R34: 84807100 | AM34: =IF('Other Item Master'!D34="","",'Other Item Master'!D34)
R35: 84807900 | AM35: =IF('Other Item Master'!D35="","",'Other Item Master'!D35)
R36: 84821011 | AM36: =IF('Other Item Master'!D36="","",'Other Item Master'!D36)
... R44: 998822 | AM44: =IF('Other Item Master'!D44="","",'Other Item Master'!D44)
AM45: =IF('Other Item Master'!D45="","",'Other Item Master'!D45)
AM46: =IF('Other Item Master'!D46="","",'Other Item Master'!D46)
AM47: =IF('Other Item Master'!D47="","",'Other Item Master'!D47)
...
